<?xml version="1.0" ?>
<!-- =================================================================================== -->
<!-- |    This document was autogenerated by xacro from robotiq_arg2f_85_model.xacro   | -->
<!-- |    EDITING THIS FILE BY HAND IS NOT RECOMMENDED                                 | -->
<!-- =================================================================================== -->
<robot name="robotiq_arg2f_85_model">
  <!-- <link name="mount_base_link">
    <inertial>
        <mass value="0.001"/>
        <inertia ixx="0" ixy="0" ixz="0" iyy="0" iyz="0" izz="0"/>
    </inertial>
    </link>

    <link name="link_x">
    <inertial>
        <mass value="0.001"/>
        <inertia ixx="0" ixy="0" ixz="0" iyy="0" iyz="0" izz="0"/>
    </inertial>
    </link>

    <link name="link_y">
    <inertial>
        <mass value="0.001"/>
        <inertia ixx="0" ixy="0" ixz="0" iyy="0" iyz="0" izz="0"/>
    </inertial>
    </link>

    <link name="link_z">
    <inertial>
        <mass value="0.001"/>
        <inertia ixx="0" ixy="0" ixz="0" iyy="0" iyz="0" izz="0"/>
    </inertial>
    </link>

    <link name="link_xy">
    <inertial>
        <mass value="0.001"/>
        <inertia ixx="0" ixy="0" ixz="0" iyy="0" iyz="0" izz="0"/>
    </inertial>
    </link>

    <link name="link_yz">
    <inertial>
        <mass value="0.001"/>
        <inertia ixx="0" ixy="0" ixz="0" iyy="0" iyz="0" izz="0"/>
    </inertial>
    </link>

    <link name="mount_link">
        <inertial>
            <mass value="0.0001"/>
            <inertia  ixx="0.0" ixy="0.0"  ixz="0.0"  iyy="0.0"  iyz="0.0"  izz="0.0" />
        </inertial>
    </link>
  
    <joint name="joint_x" type="prismatic">
        <parent link="mount_base_link"/>
        <child link="link_x"/>
        <origin xyz= "0 0 0.0"/>
        <axis xyz="1 0 0"/>
        <limit effort="1000.0" lower="-1000" upper="1000" velocity="3"/>
    </joint>

    <joint name="joint_y" type="prismatic">
        <parent link="link_x"/>
        <child link="link_y"/>
        <origin xyz= "0 0 0.0"/>
        <axis xyz="0 1 0"/>
        <limit effort="1000.0" lower="-1000" upper="1000" velocity="3"/>
    </joint>

    <joint name="joint_z" type="prismatic">
        <parent link="link_y"/>
        <child link="link_z"/>
        <origin xyz= "0 0 0.0"/>
        <axis xyz="0 0 1"/>
        <limit effort="1000.0" lower="-1000" upper="1000" velocity="3"/>
    </joint>

    <joint name="joint_revolute_1" type="revolute">
        <parent link="link_z"/>
        <child link="link_xy"/>
        <origin xyz= "0 0 0.0"/>
        <axis xyz="0 0 1"/>
        <limit effort="1000.0" lower="-1000" upper="1000" velocity="2"/>
    </joint>

    <joint name="joint_revolute_2" type="revolute">
        <parent link="link_xy"/>
        <child link="link_yz"/>
        <origin xyz= "0 0 0.0"/>
        <axis xyz="0 1 0"/>
        <limit effort="1000.0" lower="-1000" upper="1000" velocity="2"/>
    </joint>

    <joint name="joint_revolute_3" type="revolute">
        <parent link="link_yz"/>
        <child link="mount_link"/>
        <origin xyz= "0 0 0.0"/>
        <axis xyz="1 0 0"/>
        <limit effort="1000.0" lower="-1000" upper="1000" velocity="2"/>
    </joint>

  <joint name="joint_mount_gripper" type="fixed">
		<parent link="mount_link"/>
		<child link="gripper_base"/>
		<origin rpy="0.0 0.0 0.0" xyz="0.0 0.0 0.0"/>
		<axis xyz="0.0 0.0 1.0"/>
	</joint> -->

  <!-- pad gripper -->
  <link name="gripper_base">
  	<inertial>
      <origin rpy="0 0 0" xyz="0 0 0.0"/>
       <mass value="0.001"/>
       <inertia ixx="0.0" ixy="0" ixz="0" iyy="0.0" iyz="0" izz="0.0"/>
    </inertial>
  </link>
  
  <link name="left_finger_pad">
    <inertial>
      <origin rpy="0 0 0" xyz="0 0 0.0"/>
       <mass value="1"/>
       <inertia ixx="0.00020005" ixy="-4.2442E-10" ixz="-2.9069E-10" iyy="0.00017832" iyz="-3.4402E-08" izz="0.00013478"/>
    </inertial>
    <visual>
      <origin rpy="0 0 0" xyz="0 0 0"/>
      <geometry>
        <box size="0.044 0.006 0.022"/>
      </geometry>
      <material name="White">
        <color rgba="0.9 0.9 0.9 1"/>
      </material>
    </visual>
    <collision>
      <origin rpy="0 0 0" xyz="0 0 0"/>
      <geometry>
        <box size="0.044 0.006 0.022"/>
      </geometry>
      <material name="">
        <color rgba="0.9 0.0 0.0 1"/>
      </material>
    </collision>
  </link>
  <link name="right_finger_pad">
    <inertial>
      <origin rpy="0 0 0" xyz="0 0 0.0"/>
       <mass value="1"/>
       <inertia ixx="0.00020005" ixy="-4.2442E-10" ixz="-2.9069E-10" iyy="0.00017832" iyz="-3.4402E-08" izz="0.00013478"/>
    </inertial>
    <visual>
      <origin rpy="0 0 0" xyz="0 0 0"/>
      <geometry>
        <box size="0.044 0.006 0.022"/>
      </geometry>
      <material name="White">
        <color rgba="0.9 0.9 0.9 1"/>
      </material>
    </visual>
    <collision>
      <origin rpy="0 0 0" xyz="0 0 0"/>
      <geometry>
        <box size="0.044 0.006 0.022"/>
      </geometry>
      <material name="">
        <color rgba="0.9 0.0 0.0 1"/>
      </material>
    </collision>
  </link>

  <joint name="left_finger_pad_joint" type="prismatic">
    <origin rpy="0 0 0" xyz="0.022 0.0031 0."/>
    <parent link="gripper_base"/>
    <child link="left_finger_pad"/>
    <axis xyz="0 -1 0"/>
    <limit effort="200" lower="0.0" upper="0.05" velocity="0.2"/>
  </joint>
  <joint name="right_finger_pad_joint" type="prismatic">
    <origin rpy="0 0 0" xyz="0.022 -0.0031 0."/>
    <parent link="gripper_base"/>
    <child link="right_finger_pad"/>
    <axis xyz="0 1 0"/>
    <limit effort="200" lower="0.0" upper="0.05" velocity="0.2"/>
    <!-- <mimic joint="left_finger_pad_joint" multiplier="1" offset="0"/> -->
  </joint>
</robot>

