<?xml version="1.0" encoding="utf-8"?>
<!-- =================================================================================== -->
<!-- |    This document was autogenerated by xacro from franka_panda_description/robots/panda_arm.urdf.xacro | -->
<!-- |    EDITING THIS FILE BY HAND IS NOT RECOMMENDED                                 | -->
<!-- =================================================================================== -->
<robot name="gripper_panda">
  <material name="panda_white">
    <color rgba="1 1 1 1"/>
  </material>
  <material name="panda_gray">
    <color rgba="0.4 0.4 0.4 1"/>
  </material>
  <material name="silver">
    <color rgba="0.5 0.5 0.5 1"/>
  </material>




    <link name="mount_base_link">
    <inertial>
        <mass value="0"/>
        <inertia ixx="0" ixy="0" ixz="0" iyy="0" iyz="0" izz="0"/>
    </inertial>
    </link>

    <link name="link_x">
    <inertial>
        <mass value="0"/>
        <inertia ixx="0" ixy="0" ixz="0" iyy="0" iyz="0" izz="0"/>
    </inertial>
    </link>

    <link name="link_y">
    <inertial>
        <mass value="0"/>
        <inertia ixx="0" ixy="0" ixz="0" iyy="0" iyz="0" izz="0"/>
    </inertial>
    </link>

    <link name="link_z">
    <inertial>
        <mass value="0"/>
        <inertia ixx="0" ixy="0" ixz="0" iyy="0" iyz="0" izz="0"/>
    </inertial>
    </link>

    <link name="link_xy">
    <inertial>
        <mass value="0"/>
        <inertia ixx="0" ixy="0" ixz="0" iyy="0" iyz="0" izz="0"/>
    </inertial>
    </link>

    <link name="link_yz">
    <inertial>
        <mass value="0"/>
        <inertia ixx="0" ixy="0" ixz="0" iyy="0" iyz="0" izz="0"/>
    </inertial>
    </link>

    <link name="mount_link">
        <inertial>
            <mass value="0.0001"/>
            <inertia  ixx="0.0" ixy="0.0"  ixz="0.0"  iyy="0.0"  iyz="0.0"  izz="0.0" />
        </inertial>
    </link>
  
    <joint name="joint_x" type="prismatic">
        <parent link="mount_base_link"/>
        <child link="link_x"/>
        <origin xyz= "0 0 0.0"/>
        <axis xyz="1 0 0"/>
        <limit effort="1000.0" lower="-1000" upper="1000" velocity="0.5"/>
    </joint>

    <joint name="joint_y" type="prismatic">
        <parent link="link_x"/>
        <child link="link_y"/>
        <origin xyz= "0 0 0.0"/>
        <axis xyz="0 1 0"/>
        <limit effort="1000.0" lower="-1000" upper="1000" velocity="0.5"/>
    </joint>

    <joint name="joint_z" type="prismatic">
        <parent link="link_y"/>
        <child link="link_z"/>
        <origin xyz= "0 0 0.0"/>
        <axis xyz="0 0 1"/>
        <limit effort="1000.0" lower="-1000" upper="1000" velocity="0.5"/>
    </joint>

    <joint name="joint_revolute_1" type="revolute">
        <parent link="link_z"/>
        <child link="link_xy"/>
        <origin xyz= "0 0 0.0"/>
        <axis xyz="0 0 1"/>
        <limit effort="1000.0" lower="-1000" upper="1000" velocity="2"/>
    </joint>

    <joint name="joint_revolute_2" type="revolute">
        <parent link="link_xy"/>
        <child link="link_yz"/>
        <origin xyz= "0 0 0.0"/>
        <axis xyz="0 1 0"/>
        <limit effort="1000.0" lower="-1000" upper="1000" velocity="2"/>
    </joint>

    <joint name="joint_revolute_3" type="revolute">
        <parent link="link_yz"/>
        <child link="mount_link"/>
        <origin xyz= "0 0 0.0"/>
        <axis xyz="1 0 0"/>
        <limit effort="1000.0" lower="-1000" upper="1000" velocity="2"/>
    </joint>

  <joint name="joint_mount_gripper" type="fixed">
		<parent link="mount_link"/>
		<child link="panda_hand"/>
		<origin rpy="0.00000 0.00000 0.00000" xyz="0.00000 0.00000 0.00000"/>
		<axis xyz="0.00000 0.00000 1.00000"/>
	</joint>

  <!-- <link name="gripper_base">
    <inertial>
      <origin rpy="0 0 0" xyz="0 0 0"/>
      <mass value="0.0000"/>
      <inertia ixx="0.00" ixy="0.0" ixz="0.0" iyy="0.00" iyz="0.0" izz="0.00"/>
    </inertial>
  </link>

  <joint name="panda_hand_joint" type="fixed">
    <parent link="gripper_base"/>
    <child link="panda_hand"/>
    <origin rpy="0 0 0" xyz="0 0 0"/>
  </joint> -->
  <link name="panda_hand">
  	<inertial>
      <origin rpy="0 0 0" xyz="0 0 0.04"/>
       <mass value=".81"/>
       <inertia ixx="0.1" ixy="0" ixz="0" iyy="0.1" iyz="0" izz="0.1"/>
    </inertial>
    <visual>
      <geometry>
        <mesh filename="./meshes/visual/hand.obj"/>
      </geometry>
      <material name="panda_white"/>
    </visual>
    <collision>
      <geometry>
        <mesh filename="./meshes/collision/hand.obj"/>
      </geometry>
      <material name="panda_white"/>
    </collision>
  </link>
  <link name="panda_leftfinger">
       <contact>
      <friction_anchor/>
      <stiffness value="30000.0"/>
      <damping value="1000.0"/>
      <spinning_friction value="0.1"/>
      <lateral_friction value="1.0"/>
    </contact>
  	<inertial>
      <origin rpy="0 0 0" xyz="0 0.01 0.02"/>
       <mass value="0.1"/>
       <inertia ixx="0.1" ixy="0" ixz="0" iyy="0.1" iyz="0" izz="0.1"/>
    </inertial>
    <visual>
      <geometry>
        <mesh filename="./meshes/visual/finger.obj"/>
      </geometry>
      <material name="panda_white"/>
    </visual>
    <collision>
      <geometry>
        <mesh filename="./meshes/visual/finger.obj"/>
      </geometry>
      <material name="panda_white"/>
    </collision>
  </link>
  <link name="panda_rightfinger">
        <contact>
      <friction_anchor/>
      <stiffness value="30000.0"/>
      <damping value="1000.0"/>
      <spinning_friction value="0.1"/>
      <lateral_friction value="1.0"/>
    </contact>

  	<inertial>
      <origin rpy="0 0 0" xyz="0 -0.01 0.02"/>
       <mass value="0.1"/>
       <inertia ixx="0.1" ixy="0" ixz="0" iyy="0.1" iyz="0" izz="0.1"/>
    </inertial>
    <visual>
      <origin rpy="0 0 3.14159265359" xyz="0 0 0"/>
      <geometry>
        <mesh filename="./meshes/visual/finger.obj"/>
      </geometry>
      <material name="panda_white"/>
    </visual>
    <collision>
      <origin rpy="0 0 3.14159265359" xyz="0 0 0"/>
      <geometry>
        <mesh filename="./meshes/collision/finger.obj"/>
      </geometry>
      <material name="panda_white"/>
    </collision>
  </link>
  <joint name="panda_finger_joint1" type="prismatic">
    <parent link="panda_hand"/>
    <child link="panda_leftfinger"/>
    <origin rpy="0 0 0" xyz="0 0 0.0584"/>
    <axis xyz="0 1 0"/>
    <limit effort="20" lower="0.0" upper="0.04" velocity="0.2"/>
  </joint>
  <joint name="panda_finger_joint2" type="prismatic">
    <parent link="panda_hand"/>
    <child link="panda_rightfinger"/>
    <origin rpy="0 0 0" xyz="0 0 0.0584"/>
    <axis xyz="0 -1 0"/>
    <limit effort="20" lower="0.0" upper="0.04" velocity="0.2"/>
    <mimic joint="panda_finger_joint1"/>
  </joint>

   <link name="panda_grasptarget">
    <inertial>
      <origin rpy="0 0 0" xyz="0 -0.0 0.0"/>
       <mass value="0.0"/>
       <inertia ixx="0.1" ixy="0" ixz="0" iyy="0.1" iyz="0" izz="0.1"/>
    </inertial>
   </link>

   <joint name="panda_grasptarget_hand" type="fixed">
    <parent link="panda_hand"/>
    <child link="panda_grasptarget"/>
    <origin rpy="0 0 0" xyz="0 0 0.105"/>
  </joint>

</robot>
